{"uid":"fefeb021870c8af0","name":"test_get_engine","fullName":"tests.test_openai#test_get_engine","historyId":"21652c2968f040e9cb0c965f38d2b6b6","time":{"start":1683948713366,"stop":1683948721060,"duration":7694},"status":"broken","statusMessage":"azure.core.exceptions.ClientAuthenticationError: DefaultAzureCredential failed to retrieve a token from the included credentials.\nAttempted credentials:\n\tEnvironmentCredential: EnvironmentCredential authentication unavailable. Environment variables are not fully configured.\nVisit https://aka.ms/azsdk/python/identity/environmentcredential/troubleshoot to troubleshoot this issue.\n\tManagedIdentityCredential: ManagedIdentityCredential authentication unavailable. The requested identity has not been assigned to this resource.\n\tSharedTokenCacheCredential: SharedTokenCacheCredential authentication unavailable. No accounts were found in the cache.\n\tAzureCliCredential: Please run 'az login' to set up an account\n\tAzurePowerShellCredential: Az.Account module >= 2.2.0 is not installed\n\tAzureDeveloperCliCredential: Azure Developer CLI could not be found. Please visit https://aka.ms/azure-dev for installation instructions and then,once installed, authenticate to your Azure account using 'azd auth login'.\nTo mitigate this issue, please refer to the troubleshooting guidelines here at https://aka.ms/azsdk/python/identity/defaultazurecredential/troubleshoot.","statusTrace":"def test_get_engine() -> None:\n>       get_engine_test()\n\ntests/test_openai.py:26: \n_ _ _ _ _ _ _ _ _ _ _ _ _ _ _ _ _ _ _ _ _ _ _ _ _ _ _ _ _ _ _ _ _ _ _ _ _ _ _ _ \ntests/test_openai.py:13: in get_engine_test\n    context = _load_azure_openai_context()\nsrc/gpt_review/context.py:55: in _load_azure_openai_context\n    openai.api_base = os.environ[\"OPENAI_API_BASE\"] = kv_client.get_secret(\"azure-open-ai\").value  # type: ignore\n/opt/hostedtoolcache/Python/3.11.3/x64/lib/python3.11/site-packages/azure/core/tracing/decorator.py:76: in wrapper_use_tracer\n    return func(*args, **kwargs)\n/opt/hostedtoolcache/Python/3.11.3/x64/lib/python3.11/site-packages/azure/keyvault/secrets/_client.py:72: in get_secret\n    bundle = self._client.get_secret(\n/opt/hostedtoolcache/Python/3.11.3/x64/lib/python3.11/site-packages/azure/keyvault/secrets/_generated/_operations_mixin.py:1640: in get_secret\n    return mixin_instance.get_secret(vault_base_url, secret_name, secret_version, **kwargs)\n/opt/hostedtoolcache/Python/3.11.3/x64/lib/python3.11/site-packages/azure/core/tracing/decorator.py:76: in wrapper_use_tracer\n    return func(*args, **kwargs)\n/opt/hostedtoolcache/Python/3.11.3/x64/lib/python3.11/site-packages/azure/keyvault/secrets/_generated/v7_4/operations/_key_vault_client_operations.py:760: in get_secret\n    pipeline_response: PipelineResponse = self._client._pipeline.run(  # pylint: disable=protected-access\n/opt/hostedtoolcache/Python/3.11.3/x64/lib/python3.11/site-packages/azure/core/pipeline/_base.py:202: in run\n    return first_node.send(pipeline_request)\n/opt/hostedtoolcache/Python/3.11.3/x64/lib/python3.11/site-packages/azure/core/pipeline/_base.py:70: in send\n    response = self.next.send(request)\n/opt/hostedtoolcache/Python/3.11.3/x64/lib/python3.11/site-packages/azure/core/pipeline/_base.py:70: in send\n    response = self.next.send(request)\n/opt/hostedtoolcache/Python/3.11.3/x64/lib/python3.11/site-packages/azure/core/pipeline/_base.py:70: in send\n    response = self.next.send(request)\n/opt/hostedtoolcache/Python/3.11.3/x64/lib/python3.11/site-packages/azure/core/pipeline/_base.py:70: in send\n    response = self.next.send(request)\n/opt/hostedtoolcache/Python/3.11.3/x64/lib/python3.11/site-packages/azure/core/pipeline/_base.py:70: in send\n    response = self.next.send(request)\n/opt/hostedtoolcache/Python/3.11.3/x64/lib/python3.11/site-packages/azure/core/pipeline/policies/_redirect.py:156: in send\n    response = self.next.send(request)\n/opt/hostedtoolcache/Python/3.11.3/x64/lib/python3.11/site-packages/azure/core/pipeline/policies/_retry.py:448: in send\n    response = self.next.send(request)\n/opt/hostedtoolcache/Python/3.11.3/x64/lib/python3.11/site-packages/azure/core/pipeline/policies/_authentication.py:119: in send\n    request_authorized = self.on_challenge(request, response)\n/opt/hostedtoolcache/Python/3.11.3/x64/lib/python3.11/site-packages/azure/keyvault/secrets/_shared/challenge_auth_policy.py:112: in on_challenge\n    self.authorize_request(request, scope, tenant_id=challenge.tenant_id)\n/opt/hostedtoolcache/Python/3.11.3/x64/lib/python3.11/site-packages/azure/core/pipeline/policies/_authentication.py:99: in authorize_request\n    self._token = self._credential.get_token(*scopes, **kwargs)\n/opt/hostedtoolcache/Python/3.11.3/x64/lib/python3.11/site-packages/azure/identity/_credentials/default.py:214: in get_token\n    return super(DefaultAzureCredential, self).get_token(*scopes, **kwargs)\n_ _ _ _ _ _ _ _ _ _ _ _ _ _ _ _ _ _ _ _ _ _ _ _ _ _ _ _ _ _ _ _ _ _ _ _ _ _ _ _ \n\nself = <azure.identity._credentials.default.DefaultAzureCredential object at 0x7f4ec0564090>\nscopes = ('https://vault.azure.net/.default',)\nkwargs = {'tenant_id': '72f988bf-86f1-41af-91ab-2d7cd011db47'}\nhistory = [(<azure.identity._credentials.environment.EnvironmentCredential object at 0x7f4ec070b7d0>, 'EnvironmentCredential aut...ev for installation instructions and then,once installed, authenticate to your Azure account using 'azd auth login'.\")]\ncredential = <azure.identity._credentials.azd_cli.AzureDeveloperCliCredential object at 0x7f4ebf4d9e90>\nattempts = \"\\nAttempted credentials:\\n\\tEnvironmentCredential: EnvironmentCredential authentication unavailable. Environment vari...-dev for installation instructions and then,once installed, authenticate to your Azure account using 'azd auth login'.\"\nmessage = 'DefaultAzureCredential failed to retrieve a token from the included credentials.\\nAttempted credentials:\\n\\tEnvironme...er to the troubleshooting guidelines here at https://aka.ms/azsdk/python/identity/defaultazurecredential/troubleshoot.'\n\n    def get_token(self, *scopes: str, **kwargs: Any) -> AccessToken:  # pylint:disable=unused-argument\n        \"\"\"Request a token from each chained credential, in order, returning the first token received.\n    \n        This method is called automatically by Azure SDK clients.\n    \n        :param str scopes: desired scopes for the access token. This method requires at least one scope.\n            For more information about scopes, see\n            https://learn.microsoft.com/azure/active-directory/develop/scopes-oidc.\n        :raises ~azure.core.exceptions.ClientAuthenticationError: no credential in the chain provided a token\n        \"\"\"\n        within_credential_chain.set(True)\n        history = []\n        for credential in self.credentials:\n            try:\n                token = credential.get_token(*scopes, **kwargs)\n                _LOGGER.info(\"%s acquired a token from %s\", self.__class__.__name__, credential.__class__.__name__)\n                self._successful_credential = credential\n                return token\n            except CredentialUnavailableError as ex:\n                # credential didn't attempt authentication because it lacks required data or state -> continue\n                history.append((credential, ex.message))\n            except Exception as ex:  # pylint: disable=broad-except\n                # credential failed to authenticate, or something unexpectedly raised -> break\n                history.append((credential, str(ex)))\n                _LOGGER.debug(\n                    '%s.get_token failed: %s raised unexpected error \"%s\"',\n                    self.__class__.__name__,\n                    credential.__class__.__name__,\n                    ex,\n                    exc_info=True,\n                )\n                break\n    \n        within_credential_chain.set(False)\n        attempts = _get_error_message(history)\n        message = self.__class__.__name__ + \" failed to retrieve a token from the included credentials.\" + attempts \\\n                  + \"\\nTo mitigate this issue, please refer to the troubleshooting guidelines here at \" \\\n                    \"https://aka.ms/azsdk/python/identity/defaultazurecredential/troubleshoot.\"\n        _LOGGER.warning(message)\n>       raise ClientAuthenticationError(message=message)\nE       azure.core.exceptions.ClientAuthenticationError: DefaultAzureCredential failed to retrieve a token from the included credentials.\nE       Attempted credentials:\nE       \tEnvironmentCredential: EnvironmentCredential authentication unavailable. Environment variables are not fully configured.\nE       Visit https://aka.ms/azsdk/python/identity/environmentcredential/troubleshoot to troubleshoot this issue.\nE       \tManagedIdentityCredential: ManagedIdentityCredential authentication unavailable. The requested identity has not been assigned to this resource.\nE       \tSharedTokenCacheCredential: SharedTokenCacheCredential authentication unavailable. No accounts were found in the cache.\nE       \tAzureCliCredential: Please run 'az login' to set up an account\nE       \tAzurePowerShellCredential: Az.Account module >= 2.2.0 is not installed\nE       \tAzureDeveloperCliCredential: Azure Developer CLI could not be found. Please visit https://aka.ms/azure-dev for installation instructions and then,once installed, authenticate to your Azure account using 'azd auth login'.\nE       To mitigate this issue, please refer to the troubleshooting guidelines here at https://aka.ms/azsdk/python/identity/defaultazurecredential/troubleshoot.\n\n/opt/hostedtoolcache/Python/3.11.3/x64/lib/python3.11/site-packages/azure/identity/_credentials/chained.py:111: ClientAuthenticationError","flaky":false,"newFailed":false,"newBroken":false,"newPassed":false,"retriesCount":0,"retriesStatusChange":false,"beforeStages":[],"testStage":{"status":"broken","statusMessage":"azure.core.exceptions.ClientAuthenticationError: DefaultAzureCredential failed to retrieve a token from the included credentials.\nAttempted credentials:\n\tEnvironmentCredential: EnvironmentCredential authentication unavailable. Environment variables are not fully configured.\nVisit https://aka.ms/azsdk/python/identity/environmentcredential/troubleshoot to troubleshoot this issue.\n\tManagedIdentityCredential: ManagedIdentityCredential authentication unavailable. The requested identity has not been assigned to this resource.\n\tSharedTokenCacheCredential: SharedTokenCacheCredential authentication unavailable. No accounts were found in the cache.\n\tAzureCliCredential: Please run 'az login' to set up an account\n\tAzurePowerShellCredential: Az.Account module >= 2.2.0 is not installed\n\tAzureDeveloperCliCredential: Azure Developer CLI could not be found. Please visit https://aka.ms/azure-dev for installation instructions and then,once installed, authenticate to your Azure account using 'azd auth login'.\nTo mitigate this issue, please refer to the troubleshooting guidelines here at https://aka.ms/azsdk/python/identity/defaultazurecredential/troubleshoot.","statusTrace":"def test_get_engine() -> None:\n>       get_engine_test()\n\ntests/test_openai.py:26: \n_ _ _ _ _ _ _ _ _ _ _ _ _ _ _ _ _ _ _ _ _ _ _ _ _ _ _ _ _ _ _ _ _ _ _ _ _ _ _ _ \ntests/test_openai.py:13: in get_engine_test\n    context = _load_azure_openai_context()\nsrc/gpt_review/context.py:55: in _load_azure_openai_context\n    openai.api_base = os.environ[\"OPENAI_API_BASE\"] = kv_client.get_secret(\"azure-open-ai\").value  # type: ignore\n/opt/hostedtoolcache/Python/3.11.3/x64/lib/python3.11/site-packages/azure/core/tracing/decorator.py:76: in wrapper_use_tracer\n    return func(*args, **kwargs)\n/opt/hostedtoolcache/Python/3.11.3/x64/lib/python3.11/site-packages/azure/keyvault/secrets/_client.py:72: in get_secret\n    bundle = self._client.get_secret(\n/opt/hostedtoolcache/Python/3.11.3/x64/lib/python3.11/site-packages/azure/keyvault/secrets/_generated/_operations_mixin.py:1640: in get_secret\n    return mixin_instance.get_secret(vault_base_url, secret_name, secret_version, **kwargs)\n/opt/hostedtoolcache/Python/3.11.3/x64/lib/python3.11/site-packages/azure/core/tracing/decorator.py:76: in wrapper_use_tracer\n    return func(*args, **kwargs)\n/opt/hostedtoolcache/Python/3.11.3/x64/lib/python3.11/site-packages/azure/keyvault/secrets/_generated/v7_4/operations/_key_vault_client_operations.py:760: in get_secret\n    pipeline_response: PipelineResponse = self._client._pipeline.run(  # pylint: disable=protected-access\n/opt/hostedtoolcache/Python/3.11.3/x64/lib/python3.11/site-packages/azure/core/pipeline/_base.py:202: in run\n    return first_node.send(pipeline_request)\n/opt/hostedtoolcache/Python/3.11.3/x64/lib/python3.11/site-packages/azure/core/pipeline/_base.py:70: in send\n    response = self.next.send(request)\n/opt/hostedtoolcache/Python/3.11.3/x64/lib/python3.11/site-packages/azure/core/pipeline/_base.py:70: in send\n    response = self.next.send(request)\n/opt/hostedtoolcache/Python/3.11.3/x64/lib/python3.11/site-packages/azure/core/pipeline/_base.py:70: in send\n    response = self.next.send(request)\n/opt/hostedtoolcache/Python/3.11.3/x64/lib/python3.11/site-packages/azure/core/pipeline/_base.py:70: in send\n    response = self.next.send(request)\n/opt/hostedtoolcache/Python/3.11.3/x64/lib/python3.11/site-packages/azure/core/pipeline/_base.py:70: in send\n    response = self.next.send(request)\n/opt/hostedtoolcache/Python/3.11.3/x64/lib/python3.11/site-packages/azure/core/pipeline/policies/_redirect.py:156: in send\n    response = self.next.send(request)\n/opt/hostedtoolcache/Python/3.11.3/x64/lib/python3.11/site-packages/azure/core/pipeline/policies/_retry.py:448: in send\n    response = self.next.send(request)\n/opt/hostedtoolcache/Python/3.11.3/x64/lib/python3.11/site-packages/azure/core/pipeline/policies/_authentication.py:119: in send\n    request_authorized = self.on_challenge(request, response)\n/opt/hostedtoolcache/Python/3.11.3/x64/lib/python3.11/site-packages/azure/keyvault/secrets/_shared/challenge_auth_policy.py:112: in on_challenge\n    self.authorize_request(request, scope, tenant_id=challenge.tenant_id)\n/opt/hostedtoolcache/Python/3.11.3/x64/lib/python3.11/site-packages/azure/core/pipeline/policies/_authentication.py:99: in authorize_request\n    self._token = self._credential.get_token(*scopes, **kwargs)\n/opt/hostedtoolcache/Python/3.11.3/x64/lib/python3.11/site-packages/azure/identity/_credentials/default.py:214: in get_token\n    return super(DefaultAzureCredential, self).get_token(*scopes, **kwargs)\n_ _ _ _ _ _ _ _ _ _ _ _ _ _ _ _ _ _ _ _ _ _ _ _ _ _ _ _ _ _ _ _ _ _ _ _ _ _ _ _ \n\nself = <azure.identity._credentials.default.DefaultAzureCredential object at 0x7f4ec0564090>\nscopes = ('https://vault.azure.net/.default',)\nkwargs = {'tenant_id': '72f988bf-86f1-41af-91ab-2d7cd011db47'}\nhistory = [(<azure.identity._credentials.environment.EnvironmentCredential object at 0x7f4ec070b7d0>, 'EnvironmentCredential aut...ev for installation instructions and then,once installed, authenticate to your Azure account using 'azd auth login'.\")]\ncredential = <azure.identity._credentials.azd_cli.AzureDeveloperCliCredential object at 0x7f4ebf4d9e90>\nattempts = \"\\nAttempted credentials:\\n\\tEnvironmentCredential: EnvironmentCredential authentication unavailable. Environment vari...-dev for installation instructions and then,once installed, authenticate to your Azure account using 'azd auth login'.\"\nmessage = 'DefaultAzureCredential failed to retrieve a token from the included credentials.\\nAttempted credentials:\\n\\tEnvironme...er to the troubleshooting guidelines here at https://aka.ms/azsdk/python/identity/defaultazurecredential/troubleshoot.'\n\n    def get_token(self, *scopes: str, **kwargs: Any) -> AccessToken:  # pylint:disable=unused-argument\n        \"\"\"Request a token from each chained credential, in order, returning the first token received.\n    \n        This method is called automatically by Azure SDK clients.\n    \n        :param str scopes: desired scopes for the access token. This method requires at least one scope.\n            For more information about scopes, see\n            https://learn.microsoft.com/azure/active-directory/develop/scopes-oidc.\n        :raises ~azure.core.exceptions.ClientAuthenticationError: no credential in the chain provided a token\n        \"\"\"\n        within_credential_chain.set(True)\n        history = []\n        for credential in self.credentials:\n            try:\n                token = credential.get_token(*scopes, **kwargs)\n                _LOGGER.info(\"%s acquired a token from %s\", self.__class__.__name__, credential.__class__.__name__)\n                self._successful_credential = credential\n                return token\n            except CredentialUnavailableError as ex:\n                # credential didn't attempt authentication because it lacks required data or state -> continue\n                history.append((credential, ex.message))\n            except Exception as ex:  # pylint: disable=broad-except\n                # credential failed to authenticate, or something unexpectedly raised -> break\n                history.append((credential, str(ex)))\n                _LOGGER.debug(\n                    '%s.get_token failed: %s raised unexpected error \"%s\"',\n                    self.__class__.__name__,\n                    credential.__class__.__name__,\n                    ex,\n                    exc_info=True,\n                )\n                break\n    \n        within_credential_chain.set(False)\n        attempts = _get_error_message(history)\n        message = self.__class__.__name__ + \" failed to retrieve a token from the included credentials.\" + attempts \\\n                  + \"\\nTo mitigate this issue, please refer to the troubleshooting guidelines here at \" \\\n                    \"https://aka.ms/azsdk/python/identity/defaultazurecredential/troubleshoot.\"\n        _LOGGER.warning(message)\n>       raise ClientAuthenticationError(message=message)\nE       azure.core.exceptions.ClientAuthenticationError: DefaultAzureCredential failed to retrieve a token from the included credentials.\nE       Attempted credentials:\nE       \tEnvironmentCredential: EnvironmentCredential authentication unavailable. Environment variables are not fully configured.\nE       Visit https://aka.ms/azsdk/python/identity/environmentcredential/troubleshoot to troubleshoot this issue.\nE       \tManagedIdentityCredential: ManagedIdentityCredential authentication unavailable. The requested identity has not been assigned to this resource.\nE       \tSharedTokenCacheCredential: SharedTokenCacheCredential authentication unavailable. No accounts were found in the cache.\nE       \tAzureCliCredential: Please run 'az login' to set up an account\nE       \tAzurePowerShellCredential: Az.Account module >= 2.2.0 is not installed\nE       \tAzureDeveloperCliCredential: Azure Developer CLI could not be found. Please visit https://aka.ms/azure-dev for installation instructions and then,once installed, authenticate to your Azure account using 'azd auth login'.\nE       To mitigate this issue, please refer to the troubleshooting guidelines here at https://aka.ms/azsdk/python/identity/defaultazurecredential/troubleshoot.\n\n/opt/hostedtoolcache/Python/3.11.3/x64/lib/python3.11/site-packages/azure/identity/_credentials/chained.py:111: ClientAuthenticationError","steps":[],"attachments":[{"uid":"1869be0f92c92acc","name":"log","source":"1869be0f92c92acc.txt","type":"text/plain","size":1168}],"parameters":[],"stepsCount":0,"attachmentsCount":1,"shouldDisplayMessage":true,"hasContent":true},"afterStages":[],"labels":[{"name":"tag","value":"unit"},{"name":"parentSuite","value":"tests"},{"name":"suite","value":"test_openai"},{"name":"host","value":"fv-az561-723"},{"name":"thread","value":"2452-MainThread"},{"name":"framework","value":"pytest"},{"name":"language","value":"cpython3"},{"name":"package","value":"tests.test_openai"},{"name":"resultFormat","value":"allure2"}],"parameters":[],"links":[],"hidden":false,"retry":false,"extra":{"severity":"normal","retries":[],"categories":[{"name":"Test defects","matchedStatuses":[],"flaky":false}],"history":{"statistic":{"failed":0,"broken":7,"skipped":0,"passed":0,"unknown":0,"total":7},"items":[{"uid":"40d50431bbb255f1","reportUrl":"https://microsoft.github.io/gpt-review/6//#testresult/40d50431bbb255f1","status":"broken","statusDetails":"azure.core.exceptions.ClientAuthenticationError: DefaultAzureCredential failed to retrieve a token from the included credentials.\nAttempted credentials:\n\tEnvironmentCredential: EnvironmentCredential authentication unavailable. Environment variables are not fully configured.\nVisit https://aka.ms/azsdk/python/identity/environmentcredential/troubleshoot to troubleshoot this issue.\n\tManagedIdentityCredential: ManagedIdentityCredential authentication unavailable. The requested identity has not been assigned to this resource.\n\tSharedTokenCacheCredential: SharedTokenCacheCredential authentication unavailable. No accounts were found in the cache.\n\tAzureCliCredential: Failed to invoke the Azure CLI\n\tAzurePowerShellCredential: Az.Account module >= 2.2.0 is not installed\n\tAzureDeveloperCliCredential: Azure Developer CLI could not be found. Please visit https://aka.ms/azure-dev for installation instructions and then,once installed, authenticate to your Azure account using 'azd auth login'.\nTo mitigate this issue, please refer to the troubleshooting guidelines here at https://aka.ms/azsdk/python/identity/defaultazurecredential/troubleshoot.","time":{"start":1683948373355,"stop":1683948389523,"duration":16168}},{"uid":"9a77c493f86c83b7","reportUrl":"https://microsoft.github.io/gpt-review/5//#testresult/9a77c493f86c83b7","status":"broken","statusDetails":"azure.core.exceptions.ClientAuthenticationError: DefaultAzureCredential failed to retrieve a token from the included credentials.\nAttempted credentials:\n\tEnvironmentCredential: EnvironmentCredential authentication unavailable. Environment variables are not fully configured.\nVisit https://aka.ms/azsdk/python/identity/environmentcredential/troubleshoot to troubleshoot this issue.\n\tManagedIdentityCredential: ManagedIdentityCredential authentication unavailable. The requested identity has not been assigned to this resource.\n\tSharedTokenCacheCredential: SharedTokenCacheCredential authentication unavailable. No accounts were found in the cache.\n\tAzureCliCredential: Please run 'az login' to set up an account\n\tAzurePowerShellCredential: Az.Account module >= 2.2.0 is not installed\n\tAzureDeveloperCliCredential: Azure Developer CLI could not be found. Please visit https://aka.ms/azure-dev for installation instructions and then,once installed, authenticate to your Azure account using 'azd auth login'.\nTo mitigate this issue, please refer to the troubleshooting guidelines here at https://aka.ms/azsdk/python/identity/defaultazurecredential/troubleshoot.","time":{"start":1683948135919,"stop":1683948143411,"duration":7492}},{"uid":"5cdedc617cc3c779","reportUrl":"https://microsoft.github.io/gpt-review/4//#testresult/5cdedc617cc3c779","status":"broken","statusDetails":"azure.core.exceptions.ClientAuthenticationError: DefaultAzureCredential failed to retrieve a token from the included credentials.\nAttempted credentials:\n\tEnvironmentCredential: EnvironmentCredential authentication unavailable. Environment variables are not fully configured.\nVisit https://aka.ms/azsdk/python/identity/environmentcredential/troubleshoot to troubleshoot this issue.\n\tManagedIdentityCredential: ManagedIdentityCredential authentication unavailable. The requested identity has not been assigned to this resource.\n\tSharedTokenCacheCredential: SharedTokenCacheCredential authentication unavailable. No accounts were found in the cache.\n\tAzureCliCredential: Please run 'az login' to set up an account\n\tAzurePowerShellCredential: Az.Account module >= 2.2.0 is not installed\n\tAzureDeveloperCliCredential: Azure Developer CLI could not be found. Please visit https://aka.ms/azure-dev for installation instructions and then,once installed, authenticate to your Azure account using 'azd auth login'.\nTo mitigate this issue, please refer to the troubleshooting guidelines here at https://aka.ms/azsdk/python/identity/defaultazurecredential/troubleshoot.","time":{"start":1683947941115,"stop":1683947945728,"duration":4613}},{"uid":"b17c06b0c1e63fdf","reportUrl":"https://microsoft.github.io/gpt-review/3//#testresult/b17c06b0c1e63fdf","status":"broken","statusDetails":"azure.core.exceptions.ClientAuthenticationError: DefaultAzureCredential failed to retrieve a token from the included credentials.\nAttempted credentials:\n\tEnvironmentCredential: EnvironmentCredential authentication unavailable. Environment variables are not fully configured.\nVisit https://aka.ms/azsdk/python/identity/environmentcredential/troubleshoot to troubleshoot this issue.\n\tManagedIdentityCredential: ManagedIdentityCredential authentication unavailable. The requested identity has not been assigned to this resource.\n\tSharedTokenCacheCredential: SharedTokenCacheCredential authentication unavailable. No accounts were found in the cache.\n\tAzureCliCredential: Please run 'az login' to set up an account\n\tAzurePowerShellCredential: Az.Account module >= 2.2.0 is not installed\n\tAzureDeveloperCliCredential: Azure Developer CLI could not be found. Please visit https://aka.ms/azure-dev for installation instructions and then,once installed, authenticate to your Azure account using 'azd auth login'.\nTo mitigate this issue, please refer to the troubleshooting guidelines here at https://aka.ms/azsdk/python/identity/defaultazurecredential/troubleshoot.","time":{"start":1683947443564,"stop":1683947452592,"duration":9028}},{"uid":"e66d8ea760966561","reportUrl":"https://microsoft.github.io/gpt-review/2//#testresult/e66d8ea760966561","status":"broken","statusDetails":"azure.core.exceptions.ClientAuthenticationError: DefaultAzureCredential failed to retrieve a token from the included credentials.\nAttempted credentials:\n\tEnvironmentCredential: EnvironmentCredential authentication unavailable. Environment variables are not fully configured.\nVisit https://aka.ms/azsdk/python/identity/environmentcredential/troubleshoot to troubleshoot this issue.\n\tManagedIdentityCredential: ManagedIdentityCredential authentication unavailable. The requested identity has not been assigned to this resource.\n\tSharedTokenCacheCredential: SharedTokenCacheCredential authentication unavailable. No accounts were found in the cache.\n\tAzureCliCredential: Please run 'az login' to set up an account\n\tAzurePowerShellCredential: Az.Account module >= 2.2.0 is not installed\n\tAzureDeveloperCliCredential: Azure Developer CLI could not be found. Please visit https://aka.ms/azure-dev for installation instructions and then,once installed, authenticate to your Azure account using 'azd auth login'.\nTo mitigate this issue, please refer to the troubleshooting guidelines here at https://aka.ms/azsdk/python/identity/defaultazurecredential/troubleshoot.","time":{"start":1683947106356,"stop":1683947111314,"duration":4958}},{"uid":"75b9cd55b1c0fea8","reportUrl":"https://microsoft.github.io/gpt-review/1//#testresult/75b9cd55b1c0fea8","status":"broken","statusDetails":"azure.core.exceptions.ClientAuthenticationError: DefaultAzureCredential failed to retrieve a token from the included credentials.\nAttempted credentials:\n\tEnvironmentCredential: EnvironmentCredential authentication unavailable. Environment variables are not fully configured.\nVisit https://aka.ms/azsdk/python/identity/environmentcredential/troubleshoot to troubleshoot this issue.\n\tManagedIdentityCredential: ManagedIdentityCredential authentication unavailable. The requested identity has not been assigned to this resource.\n\tSharedTokenCacheCredential: SharedTokenCacheCredential authentication unavailable. No accounts were found in the cache.\n\tAzureCliCredential: Please run 'az login' to set up an account\n\tAzurePowerShellCredential: Az.Account module >= 2.2.0 is not installed\n\tAzureDeveloperCliCredential: Azure Developer CLI could not be found. Please visit https://aka.ms/azure-dev for installation instructions and then,once installed, authenticate to your Azure account using 'azd auth login'.\nTo mitigate this issue, please refer to the troubleshooting guidelines here at https://aka.ms/azsdk/python/identity/defaultazurecredential/troubleshoot.","time":{"start":1683946508375,"stop":1683946516199,"duration":7824}}]},"tags":["unit"]},"source":"fefeb021870c8af0.json","parameterValues":[]}